Workbook

Sheet README
A1: Fixture blocks vs the outright market — 2026/27 (Premier League, Championship, League One, League Two)
A2: Built 22 Oct 2026. 92 teams · 2,036 fixtures · blocks of 4 games in each team's own date order (38 games = 9 blocks + a 2-game tail; 46 games = 11 blocks + 2).
A4: WHAT EACH SHEET IS
A5: Premier League / Championship / League One / League Two — the weekly grid: one row per team (in market order), one group of columns per block: Mkt xP, Pts, xG xP, +/-. Underneath, the fixtures in each block.
A6: Team — pick any of the 92 teams from the dropdown (B2) for its block summary and all 38/46 games with market probabilities, points, xG, xGA and xG-implied points.
A7: Blocks — every team-block (1,030 rows) with sums, filterable. Status = upcoming / in progress / complete.
A8: TeamGames — every team-game (4,072 rows): the long table everything is summed from.
A9: Matches — the 2,036 fixtures. THE ONLY INPUT SHEET: blue cells on yellow (HG, AG, Home xG, Away xG). Type or paste a result and its xG here and every other sheet recalculates.
A10: Ratings — the start-of-season strength model: Sky Bet outright odds (Aug 2026), implied probabilities, fitted rating, and the season expected-points benchmark for each team.
A11: This week — the coming week's fixtures rated on luck (points vs xG) and underlying performance (xG vs the August market): who is playing better than the points say, who worse, and which games those collide in. Rebuilt weekly.
A12: Match markets — data-only probabilities for every fixture in the next 10 days: over/under goals, BTTS, team 2+/3+, clean sheets, handicaps, half-time result, goal in both halves, HT/FT, corners. No odds involved. Tendencies — each team's season-to-date frequencies for the same things.
A13: Scanner — every live bet365 outright price vs the model's rest-of-season simulation: de-vigged market %, model %, a 50/50 blend, edge, EV, Kelly. Flagged prices first, then by model edge. A shortlist to investigate, not a tip sheet.
... A36: Option C: ask Claude to 'update the fixture blocks' - it re-fetches results and xG from the sources above and republishes both files.

Sheet Glossary
A1: The words, in plain English
A3: Expected points (Mkt xP) | B3: How many points the pre-season betting market thought a team would take from a game or a block. From Sky Bet's August outright odds turned into a strength per team, then each fixture priced home and away. Frozen for the season, so it is a fair yardstick. Arsenal at home to Coventry ≈ 2.2; away at Man City ≈ 1.0.
A4: vs expected (+/-) | B4: Points won minus expected points over the games played. Positive = ahead of the market, negative = behind.
A5: Deserved points (xG xP) | B5: The points a team would have averaged if each game were decided by the chances created (xG) rather than who finished them. Each match is replayed thousands of times from its xG.
A6: Playing (Perf) | B6: Deserved points minus expected points: whether a team is genuinely better or worse than the market thought, ignoring luck.
A7: Luck | B7: Points won minus deserved points. Positive = getting more than the chances deserved (likely to fall back); negative = unlucky (likely to bounce). This is 'playing better / worse than the points say'.
A8: z | B8: How unusual a divergence is, in standard deviations given those fixtures. Beyond ±2 is rare; within ±1 is noise.
A9: xG / xGA | B9: Expected goals for / against: the quality of chances created / allowed, added up.
A10: Finishing | B10: Goals minus expected goals on target (xGoT): finishing better or worse than the shots deserved. Usually fades.
A11: Strength / Rating | B11: The model's number for how good a team is: 0 = league average, +0.7 = title favourite, −0.8 = likely relegation side. 'Aug' from the market; 'now' after re-rating on this season's xG.
A12: Projected points (Sim) | B12: Current points plus the rest of the season simulated 10,000 times with current strengths.
A13: Season target | B13: Expected points for the whole season from the August market (matches the Spreadex points lines in the PL).
A14: Next 4 / Run-in | B14: Expected points from the next four fixtures (8+ soft, under 5 hard) / average per remaining game.
... A17: Blocks | B17: Each team's fixtures in date order cut into fours. Each block: points won / expected, and the difference.

Sheet Premier League
A1: Premier League 2026/27 — fixture blocks of 4 vs the start-of-season outright market
A2: Each block: Mkt = expected points from the pre-season market model · Pts = actual points so far · xGxP = expected points implied by match xG · +/- = Pts minus Mkt xP for the games already played.
A4: Season to date | L4: Block 1 | P4: Block 2 | T4: Block 3 | X4: Block 4 | AB4: Block 5 | AF4: Block 6 | AJ4: Block 7 | AN4: Block 8 | AR4: Block 9 | AV4: Block 10
A5: Team | B5: Mkt rank | C5: Season Mkt xP | D5: P | E5: Pts | F5: Mkt xP (played) | G5: Pts +/- | H5: xG xP | I5: xGxP +/- | J5: xG | K5: xGA | L5: Mkt | M5: Pts | N5: xGxP | O5: +/- | P5: Mkt | Q5: Pts | R5: xGxP | S5: +/- | T5: Mkt | U5: Pts | V5: xGxP | W5: +/- | X5: Mkt | Y5: Pts | Z5: xGxP | AA5: +/- | AB5: Mkt | AC5: Pts | AD5: xGxP | AE5: +/- | AF5: Mkt | AG5: Pts | AH5: xGxP | AI5: +/- | AJ5: Mkt | AK5: Pts | AL5: xGxP | AM5: +/- | AN5: Mkt | AO5: Pts | AP5: xGxP | AQ5: +/- | AR5: Mkt | AS5: Pts | AT5: xGxP | AU5: +/- | AV5: Mkt | AW5: Pts | AX5: xGxP | AY5: +/-
A6: Arsenal | B6: 1 | C6: =IFERROR(INDEX(Ratings!$F:$F,MATCH($A6,Ratings!$C:$C,0)),"") | D6: =SUMIFS(TeamGames!$X$2:$X$4073,TeamGames!$D$2:$D$4073,$A6) | E6: =SUMIFS(TeamGames!$O$2:$O$4073,TeamGames!$D$2:$D$4073,$A6) | F6: =SUMIFS(TeamGames!$S$2:$S$4073,TeamGames!$D$2:$D$4073,$A6,TeamGames!$X$2:$X$4073,1) | G6: =IF(D6=0,"",E6-F6) | H6: =SUMIFS(TeamGames!$W$2:$W$4073,TeamGames!$D$2:$D$4073,$A6) | I6: =IF(D6=0,"",H6-F6) | J6: =SUMIFS(TeamGames!$T$2:$T$4073,TeamGames!$D$2:$D$4073,$A6) | K6: =SUMIFS(TeamGames!$U$2:$U$4073,TeamGames!$D$2:$D$4073,$A6) | L6: =IFERROR(INDEX(Blocks!$N$2:$N$1065,MATCH($A6&"|1",Blocks!$A$2:$A$1065,0)),"") | M6: =IF(IFERROR(INDEX(Blocks!$M$2:$M$1065,MATCH($A6&"|1",Blocks!$A$2:$A$1065,0)),"")=0,"",IFERROR(INDEX(Blocks!$P$2:$P$1065,MATCH($A6&"|1",Blocks!$A$2:$A$1065,0)),"")) | N6: =IF(IFERROR(INDEX(Blocks!$M$2:$M$1065,MATCH($A6&"|1",Blocks!$A$2:$A$1065,0)),"")=0,"",IFERROR(INDEX(Blocks!$S$2:$S$1065,MATCH($A6&"|1",Blocks!$A$2:$A$1065,0)),"")) | O6: =IFERROR(INDEX(Blocks!$T$2:$T$1065,MATCH($A6&"|1",Blocks!$A$2:$A$1065,0)),"") | P6: =IFERROR(INDEX(Blocks!$N$2:$N$1065,MATCH($A6&"|2",Blocks!$A$2:$A$1065,0)),"") | Q6: =IF(IFERROR(INDEX(Blocks!$M$2:$M$1065,MATCH($A6&"|2",Blocks!$A$2:$A$1065,0)),"")=0,"",IFERROR(INDEX(Blocks!$P$2:$P$1065,MATCH($A6&"|2",Blocks!$A$2:$A$1065,0)),"")) | R6: =IF(IFERROR(INDEX(Blocks!$M$2:$M$1065,MATCH($A6&"|2",Blocks!$A$2:$A$1065,0)),"")=0,"",IFERROR(INDEX(Blocks!$S$2:$S$1065,MATCH($A6&"|2",Blocks!$A$2:$A$1065,0)),"")) | S6: =IFERROR(INDEX(Blocks!$T$2:$T$1065,MATCH($A6&"|2",Blocks!$A$2:$A$1065,0)),"") | T6: =IFERROR(INDEX(Blocks!$N$2:$N$1065,MATCH($A6&"|3",Blocks!$A$2:$A$1065,0)),"") | U6: =IF(IFERROR(INDEX(Blocks!$M$2:$M$1065,MATCH($A6&"|3",Blocks!$A$2:$A$1065,0)),"")=0,"",IFERROR(INDEX(Blocks!$P$2:$P$1065,MATCH($A6&"|3",Blocks!$A$2:$A$1065,0)),"")) | V6: =IF(IFERROR(INDEX(Blocks!$M$2:$M$1065,MATCH($A6&"|3",Blocks!$A$2:$A$1065,0)),"")=0,"",IFERROR(INDEX(Blocks!$S$2:$S$1065,MATCH($A6&"|3",Blocks!$A$2:$A$1065,0)),"")) | W6: =IFERROR(INDEX(Blocks!$T$2:$T$1065,MATCH($A6&"|3",Blocks!$A$2:$A$1065,0)),"") | X6: =IFERROR(INDEX(Blocks!$N$2:$N$1065,MATCH($A6&"|4",Blocks!$A$2:$A$1065,0)),"") | Y6: =IF(IFERROR(INDEX(Blocks!$M$2:$M$1065,MATCH($A6&"|4",Blocks!$A$2:$A$1065,0)),"")=0,"",IFERROR(INDEX(Blocks!$P$2:$P$1065,MATCH($A6&"|4",Blocks!$A$2:$A$1065,0)),"")) | Z6: =IF(IFERROR(INDEX(Blocks!$M$2:$M$1065,MATCH($A6&"|4",Blocks!$A$2:$A$1065,0)),"")=0,"",IFERROR(INDEX(Blocks!$S$2:$S$1065,MATCH($A6&"|4",Blocks!$A$2:$A$1065,0)),"")) | AA6: =IFERROR(INDEX(Blocks!$T$2:$T$1065,MATCH($A6&"|4",Blocks!$A$2:$A$1065,0)),"") | AB6: =IFERROR(INDEX(Blocks!$N$2:$N$1065,MATCH($A6&"|5",Blocks!$A$2:$A$1065,0)),"") | AC6: =IF(IFERROR(INDEX(Blocks!$M$2:$M$1065,MATCH($A6&"|5",Blocks!$A$2:$A$1065,0)),"")=0,"",IFERROR(INDEX(Blocks!$P$2:$P$1065,MATCH($A6&"|5",Blocks!$A$2:$A$1065,0)),"")) | AD6: =IF(IFERROR(INDEX(Blocks!$M$2:$M$1065,MATCH($A6&"|5",Blocks!$A$2:$A$1065,0)),"")=0,"",IFERROR(INDEX(Blocks!$S$2:$S$1065,MATCH($A6&"|5",Blocks!$A$2:$A$1065,0)),"")) | AE6: =IFERROR(INDEX(Blocks!$T$2:$T$1065,MATCH($A6&"|5",Blocks!$A$2:$A$1065,0)),"") | AF6: =IFERROR(INDEX(Blocks!$N$2:$N$1065,MATCH($A6&"|6",Blocks!$A$2:$A$1065,0)),"") | AG6: =IF(IFERROR(INDEX(Blocks!$M$2:$M$1065,MATCH($A6&"|6",Blocks!$A$2:$A$1065,0)),"")=0,"",IFERROR(INDEX(Blocks!$P$2:$P$1065,MATCH($A6&"|6",Blocks!$A$2:$A$1065,0)),"")) | AH6: =IF(IFERROR(INDEX(Blocks!$M$2:$M$1065,MATCH($A6&"|6",Blocks!$A$2:$A$1065,0)),"")=0,"",IFERROR(INDEX(Blocks!$S$2:$S$1065,MATCH($A6&"|6",Blocks!$A$2:$A$1065,0)),"")) | AI6: =IFERROR(INDEX(Blocks!$T$2:$T$1065,MATCH($A6&"|6",Blocks!$A$2:$A$1065,0)),"") | AJ6: =IFERROR(INDEX(Blocks!$N$2:$N$1065,MATCH($A6&"|7",Blocks!$A$2:$A$1065,0)),"") | AK6: =IF(IFERROR(INDEX(Blocks!$M$2:$M$1065,MATCH($A6&"|7",Blocks!$A$2:$A$1065,0)),"")=0,"",IFERROR(INDEX(Blocks!$P$2:$P$1065,MATCH($A6&"|7",Blocks!$A$2:$A$1065,0)),"")) | AL6: =IF(IFERROR(INDEX(Blocks!$M$2:$M$1065,MATCH($A6&"|7",Blocks!$A$2:$A$1065,0)),"")=0,"",IFERROR(INDEX(Blocks!$S$2:$S$1065,MATCH($A6&"|7",Blocks!$A$2:$A$1065,0)),"")) | AM6: =IFERROR(INDEX(Blocks!$T$2:$T$1065,MATCH($A6&"|7",Blocks!$A$2:$A$1065,0)),"") | AN6: =IFERROR(INDEX(Blocks!$N$2:$N$1065,MATCH($A6&"|8",Blocks!$A$2:$A$1065,0)),"") | AO6: =IF(IFERROR(INDEX(Blocks!$M$2:$M$1065,MATCH($A6&"|8",Blocks!$A$2:$A$1065,0)),"")=0,"",IFERROR(INDEX(Blocks!$P$2:$P$1065,MATCH($A6&"|8",Blocks!$A$2:$A$1065,0)),"")) | AP6: =IF(IFERROR(INDEX(Blocks!$M$2:$M$1065,MATCH($A6&"|8",Blocks!$A$2:$A$1065,0)),"")=0,"",IFERROR(INDEX(Blocks!$S$2:$S$1065,MATCH($A6&"|8",Blocks!$A$2:$A$1065,0)),"")) | AQ6: =IFERROR(INDEX(Blocks!$T$2:$T$1065,MATCH($A6&"|8",Blocks!$A$2:$A$1065,0)),"") | AR6: =IFERROR(INDEX(Blocks!$N$2:$N$1065,MATCH($A6&"|9",Blocks!$A$2:$A$1065,0)),"") | AS6: =IF(IFERROR(INDEX(Blocks!$M$2:$M$1065,MATCH($A6&"|9",Blocks!$A$2:$A$1065,0)),"")=0,"",IFERROR(INDEX(Blocks!$P$2:$P$1065,MATCH($A6&"|9",Blocks!$A$2:$A$1065,0)),"")) | AT6: =IF(IFERROR(INDEX(Blocks!$M$2:$M$1065,MATCH($A6&"|9",Blocks!$A$2:$A$1065,0)),"")=0,"",IFERROR(INDEX(Blocks!$S$2:$S$1065,MATCH($A6&"|9",Blocks!$A$2:$A$1065,0)),"")) | AU6: =IFERROR(INDEX(Blocks!$T$2:$T$1065,MATCH($A6&"|9",Blocks!$A$2:$A$1065,0)),"") | AV6: =IFERROR(INDEX(Blocks!$N$2:$N$1065,MATCH($A6&"|10",Blocks!$A$2:$A$1065,0)),"") | AW6: =IF(IFERROR(INDEX(Blocks!$M$2:$M$1065,MATCH($A6&"|10",Blocks!$A$2:$A$1065,0)),"")=0,"",IFERROR(INDEX(Blocks!$P$2:$P$1065,MATCH($A6&"|10",Blocks!$A$2:$A$1065,0)),"")) | AX6: =IF(IFERROR(INDEX(Blocks!$M$2:$M$1065,MATCH($A6&"|10",Blocks!$A$2:$A$1065,0)),"")=0,"",IFERROR(INDEX(Blocks!$S$2:$S$1065,MATCH($A6&"|10",Blocks!$A$2:$A$1065,0)),"")) | AY6: =IFERROR(INDEX(Blocks!$T$2:$T$1065,MATCH($A6&"|10",Blocks!$A$2:$A$1065,0)),"")
A7: Man City | B7: 2 | C7: =IFERROR(INDEX(Ratings!$F:$F,MATCH($A7,Ratings!$C:$C,0)),"") | D7: =SUMIFS(TeamGames!$X$2:$X$4073,TeamGames!$D$2:$D$4073,$A7) | E7: =SUMIFS(TeamGames!$O$2:$O$4073,TeamGames!$D$2:$D$4073,$A7) | F7: =SUMIFS(TeamGames!$S$2:$S$4073,TeamGames!$D$2:$D$4073,$A7,TeamGames!$X$2:$X$4073,1) | G7: =IF(D7=0,"",E7-F7) | H7: =SUMIFS(TeamGames!$W$2:$W$4073,TeamGames!$D$2:$D$4073,$A7) | I7: =IF(D7=0,"",H7-F7) | J7: =SUMIFS(TeamGames!$T$2:$T$4073,TeamGames!$D$2:$D$4073,$A7) | K7: =SUMIFS(TeamGames!$U$2:$U$4073,TeamGames!$D$2:$D$4073,$A7) | L7: =IFERROR(INDEX(Blocks!$N$2:$N$1065,MATCH($A7&"|1",Blocks!$A$2:$A$1065,0)),"") | M7: =IF(IFERROR(INDEX(Blocks!$M$2:$M$1065,MATCH($A7&"|1",Blocks!$A$2:$A$1065,0)),"")=0,"",IFERROR(INDEX(Blocks!$P$2:$P$1065,MATCH($A7&"|1",Blocks!$A$2:$A$1065,0)),"")) | N7: =IF(IFERROR(INDEX(Blocks!$M$2:$M$1065,MATCH($A7&"|1",Blocks!$A$2:$A$1065,0)),"")=0,"",IFERROR(INDEX(Blocks!$S$2:$S$1065,MATCH($A7&"|1",Blocks!$A$2:$A$1065,0)),"")) | O7: =IFERROR(INDEX(Blocks!$T$2:$T$1065,MATCH($A7&"|1",Blocks!$A$2:$A$1065,0)),"") | P7: =IFERROR(INDEX(Blocks!$N$2:$N$1065,MATCH($A7&"|2",Blocks!$A$2:$A$1065,0)),"") | Q7: =IF(IFERROR(INDEX(Blocks!$M$2:$M$1065,MATCH($A7&"|2",Blocks!$A$2:$A$1065,0)),"")=0,"",IFERROR(INDEX(Blocks!$P$2:$P$1065,MATCH($A7&"|2",Blocks!$A$2:$A$1065,0)),"")) | R7: =IF(IFERROR(INDEX(Blocks!$M$2:$M$1065,MATCH($A7&"|2",Blocks!$A$2:$A$1065,0)),"")=0,"",IFERROR(INDEX(Blocks!$S$2:$S$1065,MATCH($A7&"|2",Blocks!$A$2:$A$1065,0)),"")) | S7: =IFERROR(INDEX(Blocks!$T$2:$T$1065,MATCH($A7&"|2",Blocks!$A$2:$A$1065,0)),"") | T7: =IFERROR(INDEX(Blocks!$N$2:$N$1065,MATCH($A7&"|3",Blocks!$A$2:$A$1065,0)),"") | U7: =IF(IFERROR(INDEX(Blocks!$M$2:$M$1065,MATCH($A7&"|3",Blocks!$A$2:$A$1065,0)),"")=0,"",IFERROR(INDEX(Blocks!$P$2:$P$1065,MATCH($A7&"|3",Blocks!$A$2:$A$1065,0)),"")) | V7: =IF(IFERROR(INDEX(Blocks!$M$2:$M$1065,MATCH($A7&"|3",Blocks!$A$2:$A$1065,0)),"")=0,"",IFERROR(INDEX(Blocks!$S$2:$S$1065,MATCH($A7&"|3",Blocks!$A$2:$A$1065,0)),"")) | W7: =IFERROR(INDEX(Blocks!$T$2:$T$1065,MATCH($A7&"|3",Blocks!$A$2:$A$1065,0)),"") | X7: =IFERROR(INDEX(Blocks!$N$2:$N$1065,MATCH($A7&"|4",Blocks!$A$2:$A$1065,0)),"") | Y7: =IF(IFERROR(INDEX(Blocks!$M$2:$M$1065,MATCH($A7&"|4",Blocks!$A$2:$A$1065,0)),"")=0,"",IFERROR(INDEX(Blocks!$P$2:$P$1065,MATCH($A7&"|4",Blocks!$A$2:$A$1065,0)),"")) | Z7: =IF(IFERROR(INDEX(Blocks!$M$2:$M$1065,MATCH($A7&"|4",Blocks!$A$2:$A$1065,0)),"")=0,"",IFERROR(INDEX(Blocks!$S$2:$S$1065,MATCH($A7&"|4",Blocks!$A$2:$A$1065,0)),"")) | AA7: =IFERROR(INDEX(Blocks!$T$2:$T$1065,MATCH($A7&"|4",Blocks!$A$2:$A$1065,0)),"") | AB7: =IFERROR(INDEX(Blocks!$N$2:$N$1065,MATCH($A7&"|5",Blocks!$A$2:$A$1065,0)),"") | AC7: =IF(IFERROR(INDEX(Blocks!$M$2:$M$1065,MATCH($A7&"|5",Blocks!$A$2:$A$1065,0)),"")=0,"",IFERROR(INDEX(Blocks!$P$2:$P$1065,MATCH($A7&"|5",Blocks!$A$2:$A$1065,0)),"")) | AD7: =IF(IFERROR(INDEX(Blocks!$M$2:$M$1065,MATCH($A7&"|5",Blocks!$A$2:$A$1065,0)),"")=0,"",IFERROR(INDEX(Blocks!$S$2:$S$1065,MATCH($A7&"|5",Blocks!$A$2:$A$1065,0)),"")) | AE7: =IFERROR(INDEX(Blocks!$T$2:$T$1065,MATCH($A7&"|5",Blocks!$A$2:$A$1065,0)),"") | AF7: =IFERROR(INDEX(Blocks!$N$2:$N$1065,MATCH($A7&"|6",Blocks!$A$2:$A$1065,0)),"") | AG7: =IF(IFERROR(INDEX(Blocks!$M$2:$M$1065,MATCH($A7&"|6",Blocks!$A$2:$A$1065,0)),"")=0,"",IFERROR(INDEX(Blocks!$P$2:$P$1065,MATCH($A7&"|6",Blocks!$A$2:$A$1065,0)),"")) | AH7: =IF(IFERROR(INDEX(Blocks!$M$2:$M$1065,MATCH($A7&"|6",Blocks!$A$2:$A$1065,0)),"")=0,"",IFERROR(INDEX(Blocks!$S$2:$S$1065,MATCH($A7&"|6",Blocks!$A$2:$A$1065,0)),"")) | AI7: =IFERROR(INDEX(Blocks!$T$2:$T$1065,MATCH($A7&"|6",Blocks!$A$2:$A$1065,0)),"") | AJ7: =IFERROR(INDEX(Blocks!$N$2:$N$1065,MATCH($A7&"|7",Blocks!$A$2:$A$1065,0)),"") | AK7: =IF(IFERROR(INDEX(Blocks!$M$2:$M$1065,MATCH($A7&"|7",Blocks!$A$2:$A$1065,0)),"")=0,"",IFERROR(INDEX(Blocks!$P$2:$P$1065,MATCH($A7&"|7",Blocks!$A$2:$A$1065,0)),"")) | AL7: =IF(IFERROR(INDEX(Blocks!$M$2:$M$1065,MATCH($A7&"|7",Blocks!$A$2:$A$1065,0)),"")=0,"",IFERROR(INDEX(Blocks!$S$2:$S$1065,MATCH($A7&"|7",Blocks!$A$2:$A$1065,0)),"")) | AM7: =IFERROR(INDEX(Blocks!$T$2:$T$1065,MATCH($A7&"|7",Blocks!$A$2:$A$1065,0)),"") | AN7: =IFERROR(INDEX(Blocks!$N$2:$N$1065,MATCH($A7&"|8",Blocks!$A$2:$A$1065,0)),"") | AO7: =IF(IFERROR(INDEX(Blocks!$M$2:$M$1065,MATCH($A7&"|8",Blocks!$A$2:$A$1065,0)),"")=0,"",IFERROR(INDEX(Blocks!$P$2:$P$1065,MATCH($A7&"|8",Blocks!$A$2:$A$1065,0)),"")) | AP7: =IF(IFERROR(INDEX(Blocks!$M$2:$M$1065,MATCH($A7&"|8",Blocks!$A$2:$A$1065,0)),"")=0,"",IFERROR(INDEX(Blocks!$S$2:$S$1065,MATCH($A7&"|8",Blocks!$A$2:$A$1065,0)),"")) | AQ7: =IFERROR(INDEX(Blocks!$T$2:$T$1065,MATCH($A7&"|8",Blocks!$A$2:$A$1065,0)),"") | AR7: =IFERROR(INDEX(Blocks!$N$2:$N$1065,MATCH($A7&"|9",Blocks!$A$2:$A$1065,0)),"") | AS7: =IF(IFERROR(INDEX(Blocks!$M$2:$M$1065,MATCH($A7&"|9",Blocks!$A$2:$A$1065,0)),"")=0,"",IFERROR(INDEX(Blocks!$P$2:$P$1065,MATCH($A7&"|9",Blocks!$A$2:$A$1065,0)),"")) | AT7: =IF(IFERROR(INDEX(Blocks!$M$2:$M$1065,MATCH($A7&"|9",Blocks!$A$2:$A$1065,0)),"")=0,"",IFERROR(INDEX(Blocks!$S$2:$S$1065,MATCH($A7&"|9",Blocks!$A$2:$A$1065,0)),"")) | AU7: =IFERROR(INDEX(Blocks!$T$2:$T$1065,MATCH($A7&"|9",Blocks!$A$2:$A$1065,0)),"") | AV7: =IFERROR(INDEX(Blocks!$N$2:$N$1065,MATCH($A7&"|10",Blocks!$A$2:$A$1065,0)),"") | AW7: =IF(IFERROR(INDEX(Blocks!$M$2:$M$1065,MATCH($A7&"|10",Blocks!$A$2:$A$1065,0)),"")=0,"",IFERROR(INDEX(Blocks!$P$2:$P$1065,MATCH($A7&"|10",Blocks!$A$2:$A$1065,0)),"")) | AX7: =IF(IFERROR(INDEX(Blocks!$M$2:$M$1065,MATCH($A7&"|10",Blocks!$A$2:$A$1065,0)),"")=0,"",IFERROR(INDEX(Blocks!$S$2:$S$1065,MATCH($A7&"|10",Blocks!$A$2:$A$1065,0)),"")) | AY7: =IFERROR(INDEX(Blocks!$T$2:$T$1065,MATCH($A7&"|10",Blocks!$A$2:$A$1065,0)),"")
A8: Liverpool | B8: 3 | C8: =IFERROR(INDEX(Ratings!$F:$F,MATCH($A8,Ratings!$C:$C,0)),"") | D8: =SUMIFS(TeamGames!$X$2:$X$4073,TeamGames!$D$2:$D$4073,$A8) | E8: =SUMIFS(TeamGames!$O$2:$O$4073,TeamGames!$D$2:$D$4073,$A8) | F8: =SUMIFS(TeamGames!$S$2:$S$4073,TeamGames!$D$2:$D$4073,$A8,TeamGames!$X$2:$X$4073,1) | G8: =IF(D8=0,"",E8-F8) | H8: =SUMIFS(TeamGames!$W$2:$W$4073,TeamGames!$D$2:$D$4073,$A8) | I8: =IF(D8=0,"",H8-F8) | J8: =SUMIFS(TeamGames!$T$2:$T$4073,TeamGames!$D$2:$D$4073,$A8) | K8: =SUMIFS(TeamGames!$U$2:$U$4073,TeamGames!$D$2:$D$4073,$A8) | L8: =IFERROR(INDEX(Blocks!$N$2:$N$1065,MATCH($A8&"|1",Blocks!$A$2:$A$1065,0)),"") | M8: =IF(IFERROR(INDEX(Blocks!$M$2:$M$1065,MATCH($A8&"|1",Blocks!$A$2:$A$1065,0)),"")=0,"",IFERROR(INDEX(Blocks!$P$2:$P$1065,MATCH($A8&"|1",Blocks!$A$2:$A$1065,0)),"")) | N8: =IF(IFERROR(INDEX(Blocks!$M$2:$M$1065,MATCH($A8&"|1",Blocks!$A$2:$A$1065,0)),"")=0,"",IFERROR(INDEX(Blocks!$S$2:$S$1065,MATCH($A8&"|1",Blocks!$A$2:$A$1065,0)),"")) | O8: =IFERROR(INDEX(Blocks!$T$2:$T$1065,MATCH($A8&"|1",Blocks!$A$2:$A$1065,0)),"") | P8: =IFERROR(INDEX(Blocks!$N$2:$N$1065,MATCH($A8&"|2",Blocks!$A$2:$A$1065,0)),"") | Q8: =IF(IFERROR(INDEX(Blocks!$M$2:$M$1065,MATCH($A8&"|2",Blocks!$A$2:$A$1065,0)),"")=0,"",IFERROR(INDEX(Blocks!$P$2:$P$1065,MATCH($A8&"|2",Blocks!$A$2:$A$1065,0)),"")) | R8: =IF(IFERROR(INDEX(Blocks!$M$2:$M$1065,MATCH($A8&"|2",Blocks!$A$2:$A$1065,0)),"")=0,"",IFERROR(INDEX(Blocks!$S$2:$S$1065,MATCH($A8&"|2",Blocks!$A$2:$A$1065,0)),"")) | S8: =IFERROR(INDEX(Blocks!$T$2:$T$1065,MATCH($A8&"|2",Blocks!$A$2:$A$1065,0)),"") | T8: =IFERROR(INDEX(Blocks!$N$2:$N$1065,MATCH($A8&"|3",Blocks!$A$2:$A$1065,0)),"") | U8: =IF(IFERROR(INDEX(Blocks!$M$2:$M$1065,MATCH($A8&"|3",Blocks!$A$2:$A$1065,0)),"")=0,"",IFERROR(INDEX(Blocks!$P$2:$P$1065,MATCH($A8&"|3",Blocks!$A$2:$A$1065,0)),"")) | V8: =IF(IFERROR(INDEX(Blocks!$M$2:$M$1065,MATCH($A8&"|3",Blocks!$A$2:$A$1065,0)),"")=0,"",IFERROR(INDEX(Blocks!$S$2:$S$1065,MATCH($A8&"|3",Blocks!$A$2:$A$1065,0)),"")) | W8: =IFERROR(INDEX(Blocks!$T$2:$T$1065,MATCH($A8&"|3",Blocks!$A$2:$A$1065,0)),"") | X8: =IFERROR(INDEX(Blocks!$N$2:$N$1065,MATCH($A8&"|4",Blocks!$A$2:$A$1065,0)),"") | Y8: =IF(IFERROR(INDEX(Blocks!$M$2:$M$1065,MATCH($A8&"|4",Blocks!$A$2:$A$1065,0)),"")=0,"",IFERROR(INDEX(Blocks!$P$2:$P$1065,MATCH($A8&"|4",Blocks!$A$2:$A$1065,0)),"")) | Z8: =IF(IFERROR(INDEX(Blocks!$M$2:$M$1065,MATCH($A8&"|4",Blocks!$A$2:$A$1065,0)),"")=0,"",IFERROR(INDEX(Blocks!$S$2:$S$1065,MATCH($A8&"|4",Blocks!$A$2:$A$1065,0)),"")) | AA8: =IFERROR(INDEX(Blocks!$T$2:$T$1065,MATCH($A8&"|4",Blocks!$A$2:$A$1065,0)),"") | AB8: =IFERROR(INDEX(Blocks!$N$2:$N$1065,MATCH($A8&"|5",Blocks!$A$2:$A$1065,0)),"") | AC8: =IF(IFERROR(INDEX(Blocks!$M$2:$M$1065,MATCH($A8&"|5",Blocks!$A$2:$A$1065,0)),"")=0,"",IFERROR(INDEX(Blocks!$P$2:$P$1065,MATCH($A8&"|5",Blocks!$A$2:$A$1065,0)),"")) | AD8: =IF(IFERROR(INDEX(Blocks!$M$2:$M$1065,MATCH($A8&"|5",Blocks!$A$2:$A$1065,0)),"")=0,"",IFERROR(INDEX(Blocks!$S$2:$S$1065,MATCH($A8&"|5",Blocks!$A$2:$A$1065,0)),"")) | AE8: =IFERROR(INDEX(Blocks!$T$2:$T$1065,MATCH($A8&"|5",Blocks!$A$2:$A$1065,0)),"") | AF8: =IFERROR(INDEX(Blocks!$N$2:$N$1065,MATCH($A8&"|6",Blocks!$A$2:$A$1065,0)),"") | AG8: =IF(IFERROR(INDEX(Blocks!$M$2:$M$1065,MATCH($A8&"|6",Blocks!$A$2:$A$1065,0)),"")=0,"",IFERROR(INDEX(Blocks!$P$2:$P$1065,MATCH($A8&"|6",Blocks!$A$2:$A$1065,0)),"")) | AH8: =IF(IFERROR(INDEX(Blocks!$M$2:$M$1065,MATCH($A8&"|6",Blocks!$A$2:$A$1065,0)),"")=0,"",IFERROR(INDEX(Blocks!$S$2:$S$1065,MATCH($A8&"|6",Blocks!$A$2:$A$1065,0)),"")) | AI8: =IFERROR(INDEX(Blocks!$T$2:$T$1065,MATCH($A8&"|6",Blocks!$A$2:$A$1065,0)),"") | AJ8: =IFERROR(INDEX(Blocks!$N$2:$N$1065,MATCH($A8&"|7",Blocks!$A$2:$A$1065,0)),"") | AK8: =IF(IFERROR(INDEX(Blocks!$M$2:$M$1065,MATCH($A8&"|7",Blocks!$A$2:$A$1065,0)),"")=0,"",IFERROR(INDEX(Blocks!$P$2:$P$1065,MATCH($A8&"|7",Blocks!$A$2:$A$1065,0)),"")) | AL8: =IF(IFERROR(INDEX(Blocks!$M$2:$M$1065,MATCH($A8&"|7",Blocks!$A$2:$A$1065,0)),"")=0,"",IFERROR(INDEX(Blocks!$S$2:$S$1065,MATCH($A8&"|7",Blocks!$A$2:$A$1065,0)),"")) | AM8: =IFERROR(INDEX(Blocks!$T$2:$T$1065,MATCH($A8&"|7",Blocks!$A$2:$A$1065,0)),"") | AN8: =IFERROR(INDEX(Blocks!$N$2:$N$1065,MATCH($A8&"|8",Blocks!$A$2:$A$1065,0)),"") | AO8: =IF(IFERROR(INDEX(Blocks!$M$2:$M$1065,MATCH($A8&"|8",Blocks!$A$2:$A$1065,0)),"")=0,"",IFERROR(INDEX(Blocks!$P$2:$P$1065,MATCH($A8&"|8",Blocks!$A$2:$A$1065,0)),"")) | AP8: =IF(IFERROR(INDEX(Blocks!$M$2:$M$1065,MATCH($A8&"|8",Blocks!$A$2:$A$1065,0)),"")=0,"",IFERROR(INDEX(Blocks!$S$2:$S$1065,MATCH($A8&"|8",Blocks!$A$2:$A$1065,0)),"")) | AQ8: =IFERROR(INDEX(Blocks!$T$2:$T$1065,MATCH($A8&"|8",Blocks!$A$2:$A$1065,0)),"") | AR8: =IFERROR(INDEX(Blocks!$N$2:$N$1065,MATCH($A8&"|9",Blocks!$A$2:$A$1065,0)),"") | AS8: =IF(IFERROR(INDEX(Blocks!$M$2:$M$1065,MATCH($A8&"|9",Blocks!$A$2:$A$1065,0)),"")=0,"",IFERROR(INDEX(Blocks!$P$2:$P$1065,MATCH($A8&"|9",Blocks!$A$2:$A$1065,0)),"")) | AT8: =IF(IFERROR(INDEX(Blocks!$M$2:$M$1065,MATCH($A8&"|9",Blocks!$A$2:$A$1065,0)),"")=0,"",IFERROR(INDEX(Blocks!$S$2:$S$1065,MATCH($A8&"|9",Blocks!$A$2:$A$1065,0)),"")) | AU8: =IFERROR(INDEX(Blocks!$T$2:$T$1065,MATCH($A8&"|9",Blocks!$A$2:$A$1065,0)),"") | AV8: =IFERROR(INDEX(Blocks!$N$2:$N$1065,MATCH($A8&"|10",Blocks!$A$2:$A$1065,0)),"") | AW8: =IF(IFERROR(INDEX(Blocks!$M$2:$M$1065,MATCH($A8&"|10",Blocks!$A$2:$A$1065,0)),"")=0,"",IFERROR(INDEX(Blocks!$P$2:$P$1065,MATCH($A8&"|10",Blocks!$A$2:$A$1065,0)),"")) | AX8: =IF(IFERROR(INDEX(Blocks!$M$2:$M$1065,MATCH($A8&"|10",Blocks!$A$2:$A$1065,0)),"")=0,"",IFERROR(INDEX(Blocks!$S$2:$S$1065,MATCH($A8&"|10",Blocks!$A$2:$A$1065,0)),"")) | AY8: =IFERROR(INDEX(Blocks!$T$2:$T$1065,MATCH($A8&"|10",Blocks!$A$2:$A$1065,0)),"")
A9: Man Utd | B9: 4 | C9: =IFERROR(INDEX(Ratings!$F:$F,MATCH($A9,Ratings!$C:$C,0)),"") | D9: =SUMIFS(TeamGames!$X$2:$X$4073,TeamGames!$D$2:$D$4073,$A9) | E9: =SUMIFS(TeamGames!$O$2:$O$4073,TeamGames!$D$2:$D$4073,$A9) | F9: =SUMIFS(TeamGames!$S$2:$S$4073,TeamGames!$D$2:$D$4073,$A9,TeamGames!$X$2:$X$4073,1) | G9: =IF(D9=0,"",E9-F9) | H9: =SUMIFS(TeamGames!$W$2:$W$4073,TeamGames!$D$2:$D$4073,$A9) | I9: =IF(D9=0,"",H9-F9) | J9: =SUMIFS(TeamGames!$T$2:$T$4073,TeamGames!$D$2:$D$4073,$A9) | K9: =SUMIFS(TeamGames!$U$2:$U$4073,TeamGames!$D$2:$D$4073,$A9) | L9: =IFERROR(INDEX(Blocks!$N$2:$N$1065,MATCH($A9&"|1",Blocks!$A$2:$A$1065,0)),"") | M9: =IF(IFERROR(INDEX(Blocks!$M$2:$M$1065,MATCH($A9&"|1",Blocks!$A$2:$A$1065,0)),"")=0,"",IFERROR(INDEX(Blocks!$P$2:$P$1065,MATCH($A9&"|1",Blocks!$A$2:$A$1065,0)),"")) | N9: =IF(IFERROR(INDEX(Blocks!$M$2:$M$1065,MATCH($A9&"|1",Blocks!$A$2:$A$1065,0)),"")=0,"",IFERROR(INDEX(Blocks!$S$2:$S$1065,MATCH($A9&"|1",Blocks!$A$2:$A$1065,0)),"")) | O9: =IFERROR(INDEX(Blocks!$T$2:$T$1065,MATCH($A9&"|1",Blocks!$A$2:$A$1065,0)),"") | P9: =IFERROR(INDEX(Blocks!$N$2:$N$1065,MATCH($A9&"|2",Blocks!$A$2:$A$1065,0)),"") | Q9: =IF(IFERROR(INDEX(Blocks!$M$2:$M$1065,MATCH($A9&"|2",Blocks!$A$2:$A$1065,0)),"")=0,"",IFERROR(INDEX(Blocks!$P$2:$P$1065,MATCH($A9&"|2",Blocks!$A$2:$A$1065,0)),"")) | R9: =IF(IFERROR(INDEX(Blocks!$M$2:$M$1065,MATCH($A9&"|2",Blocks!$A$2:$A$1065,0)),"")=0,"",IFERROR(INDEX(Blocks!$S$2:$S$1065,MATCH($A9&"|2",Blocks!$A$2:$A$1065,0)),"")) | S9: =IFERROR(INDEX(Blocks!$T$2:$T$1065,MATCH($A9&"|2",Blocks!$A$2:$A$1065,0)),"") | T9: =IFERROR(INDEX(Blocks!$N$2:$N$1065,MATCH($A9&"|3",Blocks!$A$2:$A$1065,0)),"") | U9: =IF(IFERROR(INDEX(Blocks!$M$2:$M$1065,MATCH($A9&"|3",Blocks!$A$2:$A$1065,0)),"")=0,"",IFERROR(INDEX(Blocks!$P$2:$P$1065,MATCH($A9&"|3",Blocks!$A$2:$A$1065,0)),"")) | V9: =IF(IFERROR(INDEX(Blocks!$M$2:$M$1065,MATCH($A9&"|3",Blocks!$A$2:$A$1065,0)),"")=0,"",IFERROR(INDEX(Blocks!$S$2:$S$1065,MATCH($A9&"|3",Blocks!$A$2:$A$1065,0)),"")) | W9: =IFERROR(INDEX(Blocks!$T$2:$T$1065,MATCH($A9&"|3",Blocks!$A$2:$A$1065,0)),"") | X9: =IFERROR(INDEX(Blocks!$N$2:$N$1065,MATCH($A9&"|4",Blocks!$A$2:$A$1065,0)),"") | Y9: =IF(IFERROR(INDEX(Blocks!$M$2:$M$1065,MATCH($A9&"|4",Blocks!$A$2:$A$1065,0)),"")=0,"",IFERROR(INDEX(Blocks!$P$2:$P$1065,MATCH($A9&"|4",Blocks!$A$2:$A$1065,0)),"")) | Z9: =IF(IFERROR(INDEX(Blocks!$M$2:$M$1065,MATCH($A9&"|4",Blocks!$A$2:$A$1065,0)),"")=0,"",IFERROR(INDEX(Blocks!$S$2:$S$1065,MATCH($A9&"|4",Blocks!$A$2:$A$1065,0)),"")) | AA9: =IFERROR(INDEX(Blocks!$T$2:$T$1065,MATCH($A9&"|4",Blocks!$A$2:$A$1065,0)),"") | AB9: =IFERROR(INDEX(Blocks!$N$2:$N$1065,MATCH($A9&"|5",Blocks!$A$2:$A$1065,0)),"") | AC9: =IF(IFERROR(INDEX(Blocks!$M$2:$M$1065,MATCH($A9&"|5",Blocks!$A$2:$A$1065,0)),"")=0,"",IFERROR(INDEX(Blocks!$P$2:$P$1065,MATCH($A9&"|5",Blocks!$A$2:$A$1065,0)),"")) | AD9: =IF(IFERROR(INDEX(Blocks!$M$2:$M$1065,MATCH($A9&"|5",Blocks!$A$2:$A$1065,0)),"")=0,"",IFERROR(INDEX(Blocks!$S$2:$S$1065,MATCH($A9&"|5",Blocks!$A$2:$A$1065,0)),"")) | AE9: =IFERROR(INDEX(Blocks!$T$2:$T$1065,MATCH($A9&"|5",Blocks!$A$2:$A$1065,0)),"") | AF9: =IFERROR(INDEX(Blocks!$N$2:$N$1065,MATCH($A9&"|6",Blocks!$A$2:$A$1065,0)),"") | AG9: =IF(IFERROR(INDEX(Blocks!$M$2:$M$1065,MATCH($A9&"|6",Blocks!$A$2:$A$1065,0)),"")=0,"",IFERROR(INDEX(Blocks!$P$2:$P$1065,MATCH($A9&"|6",Blocks!$A$2:$A$1065,0)),"")) | AH9: =IF(IFERROR(INDEX(Blocks!$M$2:$M$1065,MATCH($A9&"|6",Blocks!$A$2:$A$1065,0)),"")=0,"",IFERROR(INDEX(Blocks!$S$2:$S$1065,MATCH($A9&"|6",Blocks!$A$2:$A$1065,0)),"")) | AI9: =IFERROR(INDEX(Blocks!$T$2:$T$1065,MATCH($A9&"|6",Blocks!$A$2:$A$1065,0)),"") | AJ9: =IFERROR(INDEX(Blocks!$N$2:$N$1065,MATCH($A9&"|7",Blocks!$A$2:$A$1065,0)),"") | AK9: =IF(IFERROR(INDEX(Blocks!$M$2:$M$1065,MATCH($A9&"|7",Blocks!$A$2:$A$1065,0)),"")=0,"",IFERROR(INDEX(Blocks!$P$2:$P$1065,MATCH($A9&"|7",Blocks!$A$2:$A$1065,0)),"")) | AL9: =IF(IFERROR(INDEX(Blocks!$M$2:$M$1065,MATCH($A9&"|7",Blocks!$A$2:$A$1065,0)),"")=0,"",IFERROR(INDEX(Blocks!$S$2:$S$1065,MATCH($A9&"|7",Blocks!$A$2:$A$1065,0)),"")) | AM9: =IFERROR(INDEX(Blocks!$T$2:$T$1065,MATCH($A9&"|7",Blocks!$A$2:$A$1065,0)),"") | AN9: =IFERROR(INDEX(Blocks!$N$2:$N$1065,MATCH($A9&"|8",Blocks!$A$2:$A$1065,0)),"") | AO9: =IF(IFERROR(INDEX(Blocks!$M$2:$M$1065,MATCH($A9&"|8",Blocks!$A$2:$A$1065,0)),"")=0,"",IFERROR(INDEX(Blocks!$P$2:$P$1065,MATCH($A9&"|8",Blocks!$A$2:$A$1065,0)),"")) | AP9: =IF(IFERROR(INDEX(Blocks!$M$2:$M$1065,MATCH($A9&"|8",Blocks!$A$2:$A$1065,0)),"")=0,"",IFERROR(INDEX(Blocks!$S$2:$S$1065,MATCH($A9&"|8",Blocks!$A$2:$A$1065,0)),"")) | AQ9: =IFERROR(INDEX(Blocks!$T$2:$T$1065,MATCH($A9&"|8",Blocks!$A$2:$A$1065,0)),"") | AR9: =IFERROR(INDEX(Blocks!$N$2:$N$1065,MATCH($A9&"|9",Blocks!$A$2:$A$1065,0)),"") | AS9: =IF(IFERROR(INDEX(Blocks!$M$2:$M$1065,MATCH($A9&"|9",Blocks!$A$2:$A$1065,0)),"")=0,"",IFERROR(INDEX(Blocks!$P$2:$P$1065,MATCH($A9&"|9",Blocks!$A$2:$A$1065,0)),"")) | AT9: =IF(IFERROR(INDEX(Blocks!$M$2:$M$1065,MATCH($A9&"|9",Blocks!$A$2:$A$1065,0)),"")=0,"",IFERROR(INDEX(Blocks!$S$2:$S$1065,MATCH($A9&"|9",Blocks!$A$2:$A$1065,0)),"")) | AU9: =IFERROR(INDEX(Blocks!$T$2:$T$1065,MATCH($A9&"|9",Blocks!$A$2:$A$1065,0)),"") | AV9: =IFERROR(INDEX(Blocks!$N$2:$N$1065,MATCH($A9&"|10",Blocks!$A$2:$A$1065,0)),"") | AW9: =IF(IFERROR(INDEX(Blocks!$M$2:$M$1065,MATCH($A9&"|10",Blocks!$A$2:$A$1065,0)),"")=0,"",IFERROR(INDEX(Blocks!$P$2:$P$1065,MATCH($A9&"|10",Blocks!$A$2:$A$1065,0)),"")) | AX9: =IF(IFERROR(INDEX(Blocks!$M$2:$M$1065,MATCH($A9&"|10",Blocks!$A$2:$A$1065,0)),"")=0,"",IFERROR(INDEX(Blocks!$S$2:$S$1065,MATCH($A9&"|10",Blocks!$A$2:$A$1065,0)),"")) | AY9: =IFERROR(INDEX(Blocks!$T$2:$T$1065,MATCH($A9&"|10",Blocks!$A$2:$A$1065,0)),"")
A10: Chelsea | B10: 5 | C10: =IFERROR(INDEX(Ratings!$F:$F,MATCH($A10,Ratings!$C:$C,0)),"") | D10: =SUMIFS(TeamGames!$X$2:$X$4073,TeamGames!$D$2:$D$4073,$A10) | E10: =SUMIFS(TeamGames!$O$2:$O$4073,TeamGames!$D$2:$D$4073,$A10) | F10: =SUMIFS(TeamGames!$S$2:$S$4073,TeamGames!$D$2:$D$4073,$A10,TeamGames!$X$2:$X$4073,1) | G10: =IF(D10=0,"",E10-F10) | H10: =SUMIFS(TeamGames!$W$2:$W$4073,TeamGames!$D$2:$D$4073,$A10) | I10: =IF(D10=0,"",H10-F10) | J10: =SUMIFS(TeamGames!$T$2:$T$4073,TeamGames!$D$2:$D$4073,$A10) | K10: =SUMIFS(TeamGames!$U$2:$U$4073,TeamGames!$D$2:$D$4073,$A10) | L10: =IFERROR(INDEX(Blocks!$N$2:$N$1065,MATCH($A10&"|1",Blocks!$A$2:$A$1065,0)),"") | M10: =IF(IFERROR(INDEX(Blocks!$M$2:$M$1065,MATCH($A10&"|1",Blocks!$A$2:$A$1065,0)),"")=0,"",IFERROR(INDEX(Blocks!$P$2:$P$1065,MATCH($A10&"|1",Blocks!$A$2:$A$1065,0)),"")) | N10: =IF(IFERROR(INDEX(Blocks!$M$2:$M$1065,MATCH($A10&"|1",Blocks!$A$2:$A$1065,0)),"")=0,"",IFERROR(INDEX(Blocks!$S$2:$S$1065,MATCH($A10&"|1",Blocks!$A$2:$A$1065,0)),"")) | O10: =IFERROR(INDEX(Blocks!$T$2:$T$1065,MATCH($A10&"|1",Blocks!$A$2:$A$1065,0)),"") | P10: =IFERROR(INDEX(Blocks!$N$2:$N$1065,MATCH($A10&"|2",Blocks!$A$2:$A$1065,0)),"") | Q10: =IF(IFERROR(INDEX(Blocks!$M$2:$M$1065,MATCH($A10&"|2",Blocks!$A$2:$A$1065,0)),"")=0,"",IFERROR(INDEX(Blocks!$P$2:$P$1065,MATCH($A10&"|2",Blocks!$A$2:$A$1065,0)),"")) | R10: =IF(IFERROR(INDEX(Blocks!$M$2:$M$1065,MATCH($A10&"|2",Blocks!$A$2:$A$1065,0)),"")=0,"",IFERROR(INDEX(Blocks!$S$2:$S$1065,MATCH($A10&"|2",Blocks!$A$2:$A$1065,0)),"")) | S10: =IFERROR(INDEX(Blocks!$T$2:$T$1065,MATCH($A10&"|2",Blocks!$A$2:$A$1065,0)),"") | T10: =IFERROR(INDEX(Blocks!$N$2:$N$1065,MATCH($A10&"|3",Blocks!$A$2:$A$1065,0)),"") | U10: =IF(IFERROR(INDEX(Blocks!$M$2:$M$1065,MATCH($A10&"|3",Blocks!$A$2:$A$1065,0)),"")=0,"",IFERROR(INDEX(Blocks!$P$2:$P$1065,MATCH($A10&"|3",Blocks!$A$2:$A$1065,0)),"")) | V10: =IF(IFERROR(INDEX(Blocks!$M$2:$M$1065,MATCH($A10&"|3",Blocks!$A$2:$A$1065,0)),"")=0,"",IFERROR(INDEX(Blocks!$S$2:$S$1065,MATCH($A10&"|3",Blocks!$A$2:$A$1065,0)),"")) | W10: =IFERROR(INDEX(Blocks!$T$2:$T$1065,MATCH($A10&"|3",Blocks!$A$2:$A$1065,0)),"") | X10: =IFERROR(INDEX(Blocks!$N$2:$N$1065,MATCH($A10&"|4",Blocks!$A$2:$A$1065,0)),"") | Y10: =IF(IFERROR(INDEX(Blocks!$M$2:$M$1065,MATCH($A10&"|4",Blocks!$A$2:$A$1065,0)),"")=0,"",IFERROR(INDEX(Blocks!$P$2:$P$1065,MATCH($A10&"|4",Blocks!$A$2:$A$1065,0)),"")) | Z10: =IF(IFERROR(INDEX(Blocks!$M$2:$M$1065,MATCH($A10&"|4",Blocks!$A$2:$A$1065,0)),"")=0,"",IFERROR(INDEX(Blocks!$S$2:$S$1065,MATCH($A10&"|4",Blocks!$A$2:$A$1065,0)),"")) | AA10: =IFERROR(INDEX(Blocks!$T$2:$T$1065,MATCH($A10&"|4",Blocks!$A$2:$A$1065,0)),"") | AB10: =IFERROR(INDEX(Blocks!$N$2:$N$1065,MATCH($A10&"|5",Blocks!$A$2:$A$1065,0)),"") | AC10: =IF(IFERROR(INDEX(Blocks!$M$2:$M$1065,MATCH($A10&"|5",Blocks!$A$2:$A$1065,0)),"")=0,"",IFERROR(INDEX(Blocks!$P$2:$P$1065,MATCH($A10&"|5",Blocks!$A$2:$A$1065,0)),"")) | AD10: =IF(IFERROR(INDEX(Blocks!$M$2:$M$1065,MATCH($A10&"|5",Blocks!$A$2:$A$1065,0)),"")=0,"",IFERROR(INDEX(Blocks!$S$2:$S$1065,MATCH($A10&"|5",Blocks!$A$2:$A$1065,0)),"")) | AE10: =IFERROR(INDEX(Blocks!$T$2:$T$1065,MATCH($A10&"|5",Blocks!$A$2:$A$1065,0)),"") | AF10: =IFERROR(INDEX(Blocks!$N$2:$N$1065,MATCH($A10&"|6",Blocks!$A$2:$A$1065,0)),"") | AG10: =IF(IFERROR(INDEX(Blocks!$M$2:$M$1065,MATCH($A10&"|6",Blocks!$A$2:$A$1065,0)),"")=0,"",IFERROR(INDEX(Blocks!$P$2:$P$1065,MATCH($A10&"|6",Blocks!$A$2:$A$1065,0)),"")) | AH10: =IF(IFERROR(INDEX(Blocks!$M$2:$M$1065,MATCH($A10&"|6",Blocks!$A$2:$A$1065,0)),"")=0,"",IFERROR(INDEX(Blocks!$S$2:$S$1065,MATCH($A10&"|6",Blocks!$A$2:$A$1065,0)),"")) | AI10: =IFERROR(INDEX(Blocks!$T$2:$T$1065,MATCH($A10&"|6",Blocks!$A$2:$A$1065,0)),"") | AJ10: =IFERROR(INDEX(Blocks!$N$2:$N$1065,MATCH($A10&"|7",Blocks!$A$2:$A$1065,0)),"") | AK10: =IF(IFERROR(INDEX(Blocks!$M$2:$M$1065,MATCH($A10&"|7",Blocks!$A$2:$A$1065,0)),"")=0,"",IFERROR(INDEX(Blocks!$P$2:$P$1065,MATCH($A10&"|7",Blocks!$A$2:$A$1065,0)),"")) | AL10: =IF(IFERROR(INDEX(Blocks!$M$2:$M$1065,MATCH($A10&"|7",Blocks!$A$2:$A$1065,0)),"")=0,"",IFERROR(INDEX(Blocks!$S$2:$S$1065,MATCH($A10&"|7",Blocks!$A$2:$A$1065,0)),"")) | AM10: =IFERROR(INDEX(Blocks!$T$2:$T$1065,MATCH($A10&"|7",Blocks!$A$2:$A$1065,0)),"") | AN10: =IFERROR(INDEX(Blocks!$N$2:$N$1065,MATCH($A10&"|8",Blocks!$A$2:$A$1065,0)),"") | AO10: =IF(IFERROR(INDEX(Blocks!$M$2:$M$1065,MATCH($A10&"|8",Blocks!$A$2:$A$1065,0)),"")=0,"",IFERROR(INDEX(Blocks!$P$2:$P$1065,MATCH($A10&"|8",Blocks!$A$2:$A$1065,0)),"")) | AP10: =IF(IFERROR(INDEX(Blocks!$M$2:$M$1065,MATCH($A10&"|8",Blocks!$A$2:$A$1065,0)),"")=0,"",IFERROR(INDEX(Blocks!$S$2:$S$1065,MATCH($A10&"|8",Blocks!$A$2:$A$1065,0)),"")) | AQ10: =IFERROR(INDEX(Blocks!$T$2:$T$1065,MATCH($A10&"|8",Blocks!$A$2:$A$1065,0)),"") | AR10: =IFERROR(INDEX(Blocks!$N$2:$N$1065,MATCH($A10&"|9",Blocks!$A$2:$A$1065,0)),"") | AS10: =IF(IFERROR(INDEX(Blocks!$M$2:$M$1065,MATCH($A10&"|9",Blocks!$A$2:$A$1065,0)),"")=0,"",IFERROR(INDEX(Blocks!$P$2:$P$1065,MATCH($A10&"|9",Blocks!$A$2:$A$1065,0)),"")) | AT10: =IF(IFERROR(INDEX(Blocks!$M$2:$M$1065,MATCH($A10&"|9",Blocks!$A$2:$A$1065,0)),"")=0,"",IFERROR(INDEX(Blocks!$S$2:$S$1065,MATCH($A10&"|9",Blocks!$A$2:$A$1065,0)),"")) | AU10: =IFERROR(INDEX(Blocks!$T$2:$T$1065,MATCH($A10&"|9",Blocks!$A$2:$A$1065,0)),"") | AV10: =IFERROR(INDEX(Blocks!$N$2:$N$1065,MATCH($A10&"|10",Blocks!$A$2:$A$1065,0)),"") | AW10: =IF(IFERROR(INDEX(Blocks!$M$2:$M$1065,MATCH($A10&"|10",Blocks!$A$2:$A$1065,0)),"")=0,"",IFERROR(INDEX(Blocks!$P$2:$P$1065,MATCH($A10&"|10",Blocks!$A$2:$A$1065,0)),"")) | AX10: =IF(IFERROR(INDEX(Blocks!$M$2:$M$1065,MATCH($A10&"|10",Blocks!$A$2:$A$1065,0)),"")=0,"",IFERROR(INDEX(Blocks!$S$2:$S$1065,MATCH($A10&"|10",Blocks!$A$2:$A$1065,0)),"")) | AY10: =IFERROR(INDEX(Blocks!$T$2:$T$1065,MATCH($A10&"|10",Blocks!$A$2:$A$1065,0)),"")
A11: Tottenham | B11: 6 | C11: =IFERROR(INDEX(Ratings!$F:$F,MATCH($A11,Ratings!$C:$C,0)),"") | D11: =SUMIFS(TeamGames!$X$2:$X$4073,TeamGames!$D$2:$D$4073,$A11) | E11: =SUMIFS(TeamGames!$O$2:$O$4073,TeamGames!$D$2:$D$4073,$A11) | F11: =SUMIFS(TeamGames!$S$2:$S$4073,TeamGames!$D$2:$D$4073,$A11,TeamGames!$X$2:$X$4073,1) | G11: =IF(D11=0,"",E11-F11) | H11: =SUMIFS(TeamGames!$W$2:$W$4073,TeamGames!$D$2:$D$4073,$A11) | I11: =IF(D11=0,"",H11-F11) | J11: =SUMIFS(TeamGames!$T$2:$T$4073,TeamGames!$D$2:$D$4073,$A11) | K11: =SUMIFS(TeamGames!$U$2:$U$4073,TeamGames!$D$2:$D$4073,$A11) | L11: =IFERROR(INDEX(Blocks!$N$2:$N$1065,MATCH($A11&"|1",Blocks!$A$2:$A$1065,0)),"") | M11: =IF(IFERROR(INDEX(Blocks!$M$2:$M$1065,MATCH($A11&"|1",Blocks!$A$2:$A$1065,0)),"")=0,"",IFERROR(INDEX(Blocks!$P$2:$P$1065,MATCH($A11&"|1",Blocks!$A$2:$A$1065,0)),"")) | N11: =IF(IFERROR(INDEX(Blocks!$M$2:$M$1065,MATCH($A11&"|1",Blocks!$A$2:$A$1065,0)),"")=0,"",IFERROR(INDEX(Blocks!$S$2:$S$1065,MATCH($A11&"|1",Blocks!$A$2:$A$1065,0)),"")) | O11: =IFERROR(INDEX(Blocks!$T$2:$T$1065,MATCH($A11&"|1",Blocks!$A$2:$A$1065,0)),"") | P11: =IFERROR(INDEX(Blocks!$N$2:$N$1065,MATCH($A11&"|2",Blocks!$A$2:$A$1065,0)),"") | Q11: =IF(IFERROR(INDEX(Blocks!$M$2:$M$1065,MATCH($A11&"|2",Blocks!$A$2:$A$1065,0)),"")=0,"",IFERROR(INDEX(Blocks!$P$2:$P$1065,MATCH($A11&"|2",Blocks!$A$2:$A$1065,0)),"")) | R11: =IF(IFERROR(INDEX(Blocks!$M$2:$M$1065,MATCH($A11&"|2",Blocks!$A$2:$A$1065,0)),"")=0,"",IFERROR(INDEX(Blocks!$S$2:$S$1065,MATCH($A11&"|2",Blocks!$A$2:$A$1065,0)),"")) | S11: =IFERROR(INDEX(Blocks!$T$2:$T$1065,MATCH($A11&"|2",Blocks!$A$2:$A$1065,0)),"") | T11: =IFERROR(INDEX(Blocks!$N$2:$N$1065,MATCH($A11&"|3",Blocks!$A$2:$A$1065,0)),"") | U11: =IF(IFERROR(INDEX(Blocks!$M$2:$M$1065,MATCH($A11&"|3",Blocks!$A$2:$A$1065,0)),"")=0,"",IFERROR(INDEX(Blocks!$P$2:$P$1065,MATCH($A11&"|3",Blocks!$A$2:$A$1065,0)),"")) | V11: =IF(IFERROR(INDEX(Blocks!$M$2:$M$1065,MATCH($A11&"|3",Blocks!$A$2:$A$1065,0)),"")=0,"",IFERROR(INDEX(Blocks!$S$2:$S$1065,MATCH($A11&"|3",Blocks!$A$2:$A$1065,0)),"")) | W11: =IFERROR(INDEX(Blocks!$T$2:$T$1065,MATCH($A11&"|3",Blocks!$A$2:$A$1065,0)),"") | X11: =IFERROR(INDEX(Blocks!$N$2:$N$1065,MATCH($A11&"|4",Blocks!$A$2:$A$1065,0)),"") | Y11: =IF(IFERROR(INDEX(Blocks!$M$2:$M$1065,MATCH($A11&"|4",Blocks!$A$2:$A$1065,0)),"")=0,"",IFERROR(INDEX(Blocks!$P$2:$P$1065,MATCH($A11&"|4",Blocks!$A$2:$A$1065,0)),"")) | Z11: =IF(IFERROR(INDEX(Blocks!$M$2:$M$1065,MATCH($A11&"|4",Blocks!$A$2:$A$1065,0)),"")=0,"",IFERROR(INDEX(Blocks!$S$2:$S$1065,MATCH($A11&"|4",Blocks!$A$2:$A$1065,0)),"")) | AA11: =IFERROR(INDEX(Blocks!$T$2:$T$1065,MATCH($A11&"|4",Blocks!$A$2:$A$1065,0)),"") | AB11: =IFERROR(INDEX(Blocks!$N$2:$N$1065,MATCH($A11&"|5",Blocks!$A$2:$A$1065,0)),"") | AC11: =IF(IFERROR(INDEX(Blocks!$M$2:$M$1065,MATCH($A11&"|5",Blocks!$A$2:$A$1065,0)),"")=0,"",IFERROR(INDEX(Blocks!$P$2:$P$1065,MATCH($A11&"|5",Blocks!$A$2:$A$1065,0)),"")) | AD11: =IF(IFERROR(INDEX(Blocks!$M$2:$M$1065,MATCH($A11&"|5",Blocks!$A$2:$A$1065,0)),"")=0,"",IFERROR(INDEX(Blocks!$S$2:$S$1065,MATCH($A11&"|5",Blocks!$A$2:$A$1065,0)),"")) | AE11: =IFERROR(INDEX(Blocks!$T$2:$T$1065,MATCH($A11&"|5",Blocks!$A$2:$A$1065,0)),"") | AF11: =IFERROR(INDEX(Blocks!$N$2:$N$1065,MATCH($A11&"|6",Blocks!$A$2:$A$1065,0)),"") | AG11: =IF(IFERROR(INDEX(Blocks!$M$2:$M$1065,MATCH($A11&"|6",Blocks!$A$2:$A$1065,0)),"")=0,"",IFERROR(INDEX(Blocks!$P$2:$P$1065,MATCH($A11&"|6",Blocks!$A$2:$A$1065,0)),"")) | AH11: =IF(IFERROR(INDEX(Blocks!$M$2:$M$1065,MATCH($A11&"|6",Blocks!$A$2:$A$1065,0)),"")=0,"",IFERROR(INDEX(Blocks!$S$2:$S$1065,MATCH($A11&"|6",Blocks!$A$2:$A$1065,0)),"")) | AI11: =IFERROR(INDEX(Blocks!$T$2:$T$1065,MATCH($A11&"|6",Blocks!$A$2:$A$1065,0)),"") | AJ11: =IFERROR(INDEX(Blocks!$N$2:$N$1065,MATCH($A11&"|7",Blocks!$A$2:$A$1065,0)),"") | AK11: =IF(IFERROR(INDEX(Blocks!$M$2:$M$1065,MATCH($A11&"|7",Blocks!$A$2:$A$1065,0)),"")=0,"",IFERROR(INDEX(Blocks!$P$2:$P$1065,MATCH($A11&"|7",Blocks!$A$2:$A$1065,0)),"")) | AL11: =IF(IFERROR(INDEX(Blocks!$M$2:$M$1065,MATCH($A11&"|7",Blocks!$A$2:$A$1065,0)),"")=0,"",IFERROR(INDEX(Blocks!$S$2:$S$1065,MATCH($A11&"|7",Blocks!$A$2:$A$1065,0)),"")) | AM11: =IFERROR(INDEX(Blocks!$T$2:$T$1065,MATCH($A11&"|7",Blocks!$A$2:$A$1065,0)),"") | AN11: =IFERROR(INDEX(Blocks!$N$2:$N$1065,MATCH($A11&"|8",Blocks!$A$2:$A$1065,0)),"") | AO11: =IF(IFERROR(INDEX(Blocks!$M$2:$M$1065,MATCH($A11&"|8",Blocks!$A$2:$A$1065,0)),"")=0,"",IFERROR(INDEX(Blocks!$P$2:$P$1065,MATCH($A11&"|8",Blocks!$A$2:$A$1065,0)),"")) | AP11: =IF(IFERROR(INDEX(Blocks!$M$2:$M$1065,MATCH($A11&"|8",Blocks!$A$2:$A$1065,0)),"")=0,"",IFERROR(INDEX(Blocks!$S$2:$S$1065,MATCH($A11&"|8",Blocks!$A$2:$A$1065,0)),"")) | AQ11: =IFERROR(INDEX(Blocks!$T$2:$T$1065,MATCH($A11&"|8",Blocks!$A$2:$A$1065,0)),"") | AR11: =IFERROR(INDEX(Blocks!$N$2:$N$1065,MATCH($A11&"|9",Blocks!$A$2:$A$1065,0)),"") | AS11: =IF(IFERROR(INDEX(Blocks!$M$2:$M$1065,MATCH($A11&"|9",Blocks!$A$2:$A$1065,0)),"")=0,"",IFERROR(INDEX(Blocks!$P$2:$P$1065,MATCH($A11&"|9",Blocks!$A$2:$A$1065,0)),"")) | AT11: =IF(IFERROR(INDEX(Blocks!$M$2:$M$1065,MATCH($A11&"|9",Blocks!$A$2:$A$1065,0)),"")=0,"",IFERROR(INDEX(Blocks!$S$2:$S$1065,MATCH($A11&"|9",Blocks!$A$2:$A$1065,0)),"")) | AU11: =IFERROR(INDEX(Blocks!$T$2:$T$1065,MATCH($A11&"|9",Blocks!$A$2:$A$1065,0)),"") | AV11: =IFERROR(INDEX(Blocks!$N$2:$N$1065,MATCH($A11&"|10",Blocks!$A$2:$A$1065,0)),"") | AW11: =IF(IFERROR(INDEX(Blocks!$M$2:$M$1065,MATCH($A11&"|10",Blocks!$A$2:$A$1065,0)),"")=0,"",IFERROR(INDEX(Blocks!$P$2:$P$1065,MATCH($A11&"|10",Blocks!$A$2:$A$1065,0)),"")) | AX11: =IF(IFERROR(INDEX(Blocks!$M$2:$M$1065,MATCH($A11&"|10",Blocks!$A$2:$A$1065,0)),"")=0,"",IFERROR(INDEX(Blocks!$S$2:$S$1065,MATCH($A11&"|10",Blocks!$A$2:$A$1065,0)),"")) | AY11: =IFERROR(INDEX(Blocks!$T$2:$T$1065,MATCH($A11&"|10",Blocks!$A$2:$A$1065,0)),"")
A12: Aston Villa | B12: 7 | C12: =IFERROR(INDEX(Ratings!$F:$F,MATCH($A12,Ratings!$C:$C,0)),"") | D12: =SUMIFS(TeamGames!$X$2:$X$4073,TeamGames!$D$2:$D$4073,$A12) | E12: =SUMIFS(TeamGames!$O$2:$O$4073,TeamGames!$D$2:$D$4073,$A12) | F12: =SUMIFS(TeamGames!$S$2:$S$4073,TeamGames!$D$2:$D$4073,$A12,TeamGames!$X$2:$X$4073,1) | G12: =IF(D12=0,"",E12-F12) | H12: =SUMIFS(TeamGames!$W$2:$W$4073,TeamGames!$D$2:$D$4073,$A12) | I12: =IF(D12=0,"",H12-F12) | J12: =SUMIFS(TeamGames!$T$2:$T$4073,TeamGames!$D$2:$D$4073,$A12) | K12: =SUMIFS(TeamGames!$U$2:$U$4073,TeamGames!$D$2:$D$4073,$A12) | L12: =IFERROR(INDEX(Blocks!$N$2:$N$1065,MATCH($A12&"|1",Blocks!$A$2:$A$1065,0)),"") | M12: =IF(IFERROR(INDEX(Blocks!$M$2:$M$1065,MATCH($A12&"|1",Blocks!$A$2:$A$1065,0)),"")=0,"",IFERROR(INDEX(Blocks!$P$2:$P$1065,MATCH($A12&"|1",Blocks!$A$2:$A$1065,0)),"")) | N12: =IF(IFERROR(INDEX(Blocks!$M$2:$M$1065,MATCH($A12&"|1",Blocks!$A$2:$A$1065,0)),"")=0,"",IFERROR(INDEX(Blocks!$S$2:$S$1065,MATCH($A12&"|1",Blocks!$A$2:$A$1065,0)),"")) | O12: =IFERROR(INDEX(Blocks!$T$2:$T$1065,MATCH($A12&"|1",Blocks!$A$2:$A$1065,0)),"") | P12: =IFERROR(INDEX(Blocks!$N$2:$N$1065,MATCH($A12&"|2",Blocks!$A$2:$A$1065,0)),"") | Q12: =IF(IFERROR(INDEX(Blocks!$M$2:$M$1065,MATCH($A12&"|2",Blocks!$A$2:$A$1065,0)),"")=0,"",IFERROR(INDEX(Blocks!$P$2:$P$1065,MATCH($A12&"|2",Blocks!$A$2:$A$1065,0)),"")) | R12: =IF(IFERROR(INDEX(Blocks!$M$2:$M$1065,MATCH($A12&"|2",Blocks!$A$2:$A$1065,0)),"")=0,"",IFERROR(INDEX(Blocks!$S$2:$S$1065,MATCH($A12&"|2",Blocks!$A$2:$A$1065,0)),"")) | S12: =IFERROR(INDEX(Blocks!$T$2:$T$1065,MATCH($A12&"|2",Blocks!$A$2:$A$1065,0)),"") | T12: =IFERROR(INDEX(Blocks!$N$2:$N$1065,MATCH($A12&"|3",Blocks!$A$2:$A$1065,0)),"") | U12: =IF(IFERROR(INDEX(Blocks!$M$2:$M$1065,MATCH($A12&"|3",Blocks!$A$2:$A$1065,0)),"")=0,"",IFERROR(INDEX(Blocks!$P$2:$P$1065,MATCH($A12&"|3",Blocks!$A$2:$A$1065,0)),"")) | V12: =IF(IFERROR(INDEX(Blocks!$M$2:$M$1065,MATCH($A12&"|3",Blocks!$A$2:$A$1065,0)),"")=0,"",IFERROR(INDEX(Blocks!$S$2:$S$1065,MATCH($A12&"|3",Blocks!$A$2:$A$1065,0)),"")) | W12: =IFERROR(INDEX(Blocks!$T$2:$T$1065,MATCH($A12&"|3",Blocks!$A$2:$A$1065,0)),"") | X12: =IFERROR(INDEX(Blocks!$N$2:$N$1065,MATCH($A12&"|4",Blocks!$A$2:$A$1065,0)),"") | Y12: =IF(IFERROR(INDEX(Blocks!$M$2:$M$1065,MATCH($A12&"|4",Blocks!$A$2:$A$1065,0)),"")=0,"",IFERROR(INDEX(Blocks!$P$2:$P$1065,MATCH($A12&"|4",Blocks!$A$2:$A$1065,0)),"")) | Z12: =IF(IFERROR(INDEX(Blocks!$M$2:$M$1065,MATCH($A12&"|4",Blocks!$A$2:$A$1065,0)),"")=0,"",IFERROR(INDEX(Blocks!$S$2:$S$1065,MATCH($A12&"|4",Blocks!$A$2:$A$1065,0)),"")) | AA12: =IFERROR(INDEX(Blocks!$T$2:$T$1065,MATCH($A12&"|4",Blocks!$A$2:$A$1065,0)),"") | AB12: =IFERROR(INDEX(Blocks!$N$2:$N$1065,MATCH($A12&"|5",Blocks!$A$2:$A$1065,0)),"") | AC12: =IF(IFERROR(INDEX(Blocks!$M$2:$M$1065,MATCH($A12&"|5",Blocks!$A$2:$A$1065,0)),"")=0,"",IFERROR(INDEX(Blocks!$P$2:$P$1065,MATCH($A12&"|5",Blocks!$A$2:$A$1065,0)),"")) | AD12: =IF(IFERROR(INDEX(Blocks!$M$2:$M$1065,MATCH($A12&"|5",Blocks!$A$2:$A$1065,0)),"")=0,"",IFERROR(INDEX(Blocks!$S$2:$S$1065,MATCH($A12&"|5",Blocks!$A$2:$A$1065,0)),"")) | AE12: =IFERROR(INDEX(Blocks!$T$2:$T$1065,MATCH($A12&"|5",Blocks!$A$2:$A$1065,0)),"") | AF12: =IFERROR(INDEX(Blocks!$N$2:$N$1065,MATCH($A12&"|6",Blocks!$A$2:$A$1065,0)),"") | AG12: =IF(IFERROR(INDEX(Blocks!$M$2:$M$1065,MATCH($A12&"|6",Blocks!$A$2:$A$1065,0)),"")=0,"",IFERROR(INDEX(Blocks!$P$2:$P$1065,MATCH($A12&"|6",Blocks!$A$2:$A$1065,0)),"")) | AH12: =IF(IFERROR(INDEX(Blocks!$M$2:$M$1065,MATCH($A12&"|6",Blocks!$A$2:$A$1065,0)),"")=0,"",IFERROR(INDEX(Blocks!$S$2:$S$1065,MATCH($A12&"|6",Blocks!$A$2:$A$1065,0)),"")) | AI12: =IFERROR(INDEX(Blocks!$T$2:$T$1065,MATCH($A12&"|6",Blocks!$A$2:$A$1065,0)),"") | AJ12: =IFERROR(INDEX(Blocks!$N$2:$N$1065,MATCH($A12&"|7",Blocks!$A$2:$A$1065,0)),"") | AK12: =IF(IFERROR(INDEX(Blocks!$M$2:$M$1065,MATCH($A12&"|7",Blocks!$A$2:$A$1065,0)),"")=0,"",IFERROR(INDEX(Blocks!$P$2:$P$1065,MATCH($A12&"|7",Blocks!$A$2:$A$1065,0)),"")) | AL12: =IF(IFERROR(INDEX(Blocks!$M$2:$M$1065,MATCH($A12&"|7",Blocks!$A$2:$A$1065,0)),"")=0,"",IFERROR(INDEX(Blocks!$S$2:$S$1065,MATCH($A12&"|7",Blocks!$A$2:$A$1065,0)),"")) | AM12: =IFERROR(INDEX(Blocks!$T$2:$T$1065,MATCH($A12&"|7",Blocks!$A$2:$A$1065,0)),"") | AN12: =IFERROR(INDEX(Blocks!$N$2:$N$1065,MATCH($A12&"|8",Blocks!$A$2:$A$1065,0)),"") | AO12: =IF(IFERROR(INDEX(Blocks!$M$2:$M$1065,MATCH($A12&"|8",Blocks!$A$2:$A$1065,0)),"")=0,"",IFERROR(INDEX(Blocks!$P$2:$P$1065,MATCH($A12&"|8",Blocks!$A$2:$A$1065,0)),"")) | AP12: =IF(IFERROR(INDEX(Blocks!$M$2:$M$1065,MATCH($A12&"|8",Blocks!$A$2:$A$1065,0)),"")=0,"",IFERROR(INDEX(Blocks!$S$2:$S$1065,MATCH($A12&"|8",Blocks!$A$2:$A$1065,0)),"")) | AQ12: =IFERROR(INDEX(Blocks!$T$2:$T$1065,MATCH($A12&"|8",Blocks!$A$2:$A$1065,0)),"") | AR12: =IFERROR(INDEX(Blocks!$N$2:$N$1065,MATCH($A12&"|9",Blocks!$A$2:$A$1065,0)),"") | AS12: =IF(IFERROR(INDEX(Blocks!$M$2:$M$1065,MATCH($A12&"|9",Blocks!$A$2:$A$1065,0)),"")=0,"",IFERROR(INDEX(Blocks!$P$2:$P$1065,MATCH($A12&"|9",Blocks!$A$2:$A$1065,0)),"")) | AT12: =IF(IFERROR(INDEX(Blocks!$M$2:$M$1065,MATCH($A12&"|9",Blocks!$A$2:$A$1065,0)),"")=0,"",IFERROR(INDEX(Blocks!$S$2:$S$1065,MATCH($A12&"|9",Blocks!$A$2:$A$1065,0)),"")) | AU12: =IFERROR(INDEX(Blocks!$T$2:$T$1065,MATCH($A12&"|9",Blocks!$A$2:$A$1065,0)),"") | AV12: =IFERROR(INDEX(Blocks!$N$2:$N$1065,MATCH($A12&"|10",Blocks!$A$2:$A$1065,0)),"") | AW12: =IF(IFERROR(INDEX(Blocks!$M$2:$M$1065,MATCH($A12&"|10",Blocks!$A$2:$A$1065,0)),"")=0,"",IFERROR(INDEX(Blocks!$P$2:$P$1065,MATCH($A12&"|10",Blocks!$A$2:$A$1065,0)),"")) | AX12: =IF(IFERROR(INDEX(Blocks!$M$2:$M$1065,MATCH($A12&"|10",Blocks!$A$2:$A$1065,0)),"")=0,"",IFERROR(INDEX(Blocks!$S$2:$S$1065,MATCH($A12&"|10",Blocks!$A$2:$A$1065,0)),"")) | AY12: =IFERROR(INDEX(Blocks!$T$2:$T$1065,MATCH($A12&"|10",Blocks!$A$2:$A$1065,0)),"")
A13: Brighton | B13: 8 | C13: =IFERROR(INDEX(Ratings!$F:$F,MATCH($A13,Ratings!$C:$C,0)),"") | D13: =SUMIFS(TeamGames!$X$2:$X$4073,TeamGames!$D$2:$D$4073,$A13) | E13: =SUMIFS(TeamGames!$O$2:$O$4073,TeamGames!$D$2:$D$4073,$A13) | F13: =SUMIFS(TeamGames!$S$2:$S$4073,TeamGames!$D$2:$D$4073,$A13,TeamGames!$X$2:$X$4073,1) | G13: =IF(D13=0,"",E13-F13) | H13: =SUMIFS(TeamGames!$W$2:$W$4073,TeamGames!$D$2:$D$4073,$A13) | I13: =IF(D13=0,"",H13-F13) | J13: =SUMIFS(TeamGames!$T$2:$T$4073,TeamGames!$D$2:$D$4073,$A13) | K13: =SUMIFS(TeamGames!$U$2:$U$4073,TeamGames!$D$2:$D$4073,$A13) | L13: =IFERROR(INDEX(Blocks!$N$2:$N$1065,MATCH($A13&"|1",Blocks!$A$2:$A$1065,0)),"") | M13: =IF(IFERROR(INDEX(Blocks!$M$2:$M$1065,MATCH($A13&"|1",Blocks!$A$2:$A$1065,0)),"")=0,"",IFERROR(INDEX(Blocks!$P$2:$P$1065,MATCH($A13&"|1",Blocks!$A$2:$A$1065,0)),"")) | N13: =IF(IFERROR(INDEX(Blocks!$M$2:$M$1065,MATCH($A13&"|1",Blocks!$A$2:$A$1065,0)),"")=0,"",IFERROR(INDEX(Blocks!$S$2:$S$1065,MATCH($A13&"|1",Blocks!$A$2:$A$1065,0)),"")) | O13: =IFERROR(INDEX(Blocks!$T$2:$T$1065,MATCH($A13&"|1",Blocks!$A$2:$A$1065,0)),"") | P13: =IFERROR(INDEX(Blocks!$N$2:$N$1065,MATCH($A13&"|2",Blocks!$A$2:$A$1065,0)),"") | Q13: =IF(IFERROR(INDEX(Blocks!$M$2:$M$1065,MATCH($A13&"|2",Blocks!$A$2:$A$1065,0)),"")=0,"",IFERROR(INDEX(Blocks!$P$2:$P$1065,MATCH($A13&"|2",Blocks!$A$2:$A$1065,0)),"")) | R13: =IF(IFERROR(INDEX(Blocks!$M$2:$M$1065,MATCH($A13&"|2",Blocks!$A$2:$A$1065,0)),"")=0,"",IFERROR(INDEX(Blocks!$S$2:$S$1065,MATCH($A13&"|2",Blocks!$A$2:$A$1065,0)),"")) | S13: =IFERROR(INDEX(Blocks!$T$2:$T$1065,MATCH($A13&"|2",Blocks!$A$2:$A$1065,0)),"") | T13: =IFERROR(INDEX(Blocks!$N$2:$N$1065,MATCH($A13&"|3",Blocks!$A$2:$A$1065,0)),"") | U13: =IF(IFERROR(INDEX(Blocks!$M$2:$M$1065,MATCH($A13&"|3",Blocks!$A$2:$A$1065,0)),"")=0,"",IFERROR(INDEX(Blocks!$P$2:$P$1065,MATCH($A13&"|3",Blocks!$A$2:$A$1065,0)),"")) | V13: =IF(IFERROR(INDEX(Blocks!$M$2:$M$1065,MATCH($A13&"|3",Blocks!$A$2:$A$1065,0)),"")=0,"",IFERROR(INDEX(Blocks!$S$2:$S$1065,MATCH($A13&"|3",Blocks!$A$2:$A$1065,0)),"")) | W13: =IFERROR(INDEX(Blocks!$T$2:$T$1065,MATCH($A13&"|3",Blocks!$A$2:$A$1065,0)),"") | X13: =IFERROR(INDEX(Blocks!$N$2:$N$1065,MATCH($A13&"|4",Blocks!$A$2:$A$1065,0)),"") | Y13: =IF(IFERROR(INDEX(Blocks!$M$2:$M$1065,MATCH($A13&"|4",Blocks!$A$2:$A$1065,0)),"")=0,"",IFERROR(INDEX(Blocks!$P$2:$P$1065,MATCH($A13&"|4",Blocks!$A$2:$A$1065,0)),"")) | Z13: =IF(IFERROR(INDEX(Blocks!$M$2:$M$1065,MATCH($A13&"|4",Blocks!$A$2:$A$1065,0)),"")=0,"",IFERROR(INDEX(Blocks!$S$2:$S$1065,MATCH($A13&"|4",Blocks!$A$2:$A$1065,0)),"")) | AA13: =IFERROR(INDEX(Blocks!$T$2:$T$1065,MATCH($A13&"|4",Blocks!$A$2:$A$1065,0)),"") | AB13: =IFERROR(INDEX(Blocks!$N$2:$N$1065,MATCH($A13&"|5",Blocks!$A$2:$A$1065,0)),"") | AC13: =IF(IFERROR(INDEX(Blocks!$M$2:$M$1065,MATCH($A13&"|5",Blocks!$A$2:$A$1065,0)),"")=0,"",IFERROR(INDEX(Blocks!$P$2:$P$1065,MATCH($A13&"|5",Blocks!$A$2:$A$1065,0)),"")) | AD13: =IF(IFERROR(INDEX(Blocks!$M$2:$M$1065,MATCH($A13&"|5",Blocks!$A$2:$A$1065,0)),"")=0,"",IFERROR(INDEX(Blocks!$S$2:$S$1065,MATCH($A13&"|5",Blocks!$A$2:$A$1065,0)),"")) | AE13: =IFERROR(INDEX(Blocks!$T$2:$T$1065,MATCH($A13&"|5",Blocks!$A$2:$A$1065,0)),"") | AF13: =IFERROR(INDEX(Blocks!$N$2:$N$1065,MATCH($A13&"|6",Blocks!$A$2:$A$1065,0)),"") | AG13: =IF(IFERROR(INDEX(Blocks!$M$2:$M$1065,MATCH($A13&"|6",Blocks!$A$2:$A$1065,0)),"")=0,"",IFERROR(INDEX(Blocks!$P$2:$P$1065,MATCH($A13&"|6",Blocks!$A$2:$A$1065,0)),"")) | AH13: =IF(IFERROR(INDEX(Blocks!$M$2:$M$1065,MATCH($A13&"|6",Blocks!$A$2:$A$1065,0)),"")=0,"",IFERROR(INDEX(Blocks!$S$2:$S$1065,MATCH($A13&"|6",Blocks!$A$2:$A$1065,0)),"")) | AI13: =IFERROR(INDEX(Blocks!$T$2:$T$1065,MATCH($A13&"|6",Blocks!$A$2:$A$1065,0)),"") | AJ13: =IFERROR(INDEX(Blocks!$N$2:$N$1065,MATCH($A13&"|7",Blocks!$A$2:$A$1065,0)),"") | AK13: =IF(IFERROR(INDEX(Blocks!$M$2:$M$1065,MATCH($A13&"|7",Blocks!$A$2:$A$1065,0)),"")=0,"",IFERROR(INDEX(Blocks!$P$2:$P$1065,MATCH($A13&"|7",Blocks!$A$2:$A$1065,0)),"")) | AL13: =IF(IFERROR(INDEX(Blocks!$M$2:$M$1065,MATCH($A13&"|7",Blocks!$A$2:$A$1065,0)),"")=0,"",IFERROR(INDEX(Blocks!$S$2:$S$1065,MATCH($A13&"|7",Blocks!$A$2:$A$1065,0)),"")) | AM13: =IFERROR(INDEX(Blocks!$T$2:$T$1065,MATCH($A13&"|7",Blocks!$A$2:$A$1065,0)),"") | AN13: =IFERROR(INDEX(Blocks!$N$2:$N$1065,MATCH($A13&"|8",Blocks!$A$2:$A$1065,0)),"") | AO13: =IF(IFERROR(INDEX(Blocks!$M$2:$M$1065,MATCH($A13&"|8",Blocks!$A$2:$A$1065,0)),"")=0,"",IFERROR(INDEX(Blocks!$P$2:$P$1065,MATCH($A13&"|8",Blocks!$A$2:$A$1065,0)),"")) | AP13: =IF(IFERROR(INDEX(Blocks!$M$2:$M$1065,MATCH($A13&"|8",Blocks!$A$2:$A$1065,0)),"")=0,"",IFERROR(INDEX(Blocks!$S$2:$S$1065,MATCH($A13&"|8",Blocks!$A$2:$A$1065,0)),"")) | AQ13: =IFERROR(INDEX(Blocks!$T$2:$T$1065,MATCH($A13&"|8",Blocks!$A$2:$A$1065,0)),"") | AR13: =IFERROR(INDEX(Blocks!$N$2:$N$1065,MATCH($A13&"|9",Blocks!$A$2:$A$1065,0)),"") | AS13: =IF(IFERROR(INDEX(Blocks!$M$2:$M$1065,MATCH($A13&"|9",Blocks!$A$2:$A$1065,0)),"")=0,"",IFERROR(INDEX(Blocks!$P$2:$P$1065,MATCH($A13&"|9",Blocks!$A$2:$A$1065,0)),"")) | AT13: =IF(IFERROR(INDEX(Blocks!$M$2:$M$1065,MATCH($A13&"|9",Blocks!$A$2:$A$1065,0)),"")=0,"",IFERROR(INDEX(Blocks!$S$2:$S$1065,MATCH($A13&"|9",Blocks!$A$2:$A$1065,0)),"")) | AU13: =IFERROR(INDEX(Blocks!$T$2:$T$1065,MATCH($A13&"|9",Blocks!$A$2:$A$1065,0)),"") | AV13: =IFERROR(INDEX(Blocks!$N$2:$N$1065,MATCH($A13&"|10",Blocks!$A$2:$A$1065,0)),"") | AW13: =IF(IFERROR(INDEX(Blocks!$M$2:$M$1065,MATCH($A13&"|10",Blocks!$A$2:$A$1065,0)),"")=0,"",IFERROR(INDEX(Blocks!$P$2:$P$1065,MATCH($A13&"|10",Blocks!$A$2:$A$1065,0)),"")) | AX13: =IF(IFERROR(INDEX(Blocks!$M$2:$M$1065,MATCH($A13&"|10",Blocks!$A$2:$A$1065,0)),"")=0,"",IFERROR(INDEX(Blocks!$S$2:$S$1065,MATCH($A13&"|10",Blocks!$A$2:$A$1065,0)),"")) | AY13: =IFERROR(INDEX(Blocks!$T$2:$T$1065,MATCH($A13&"|10",Blocks!$A$2:$A$1065,0)),"")
A14: Newcastle | B14: 9 | C14: =IFERROR(INDEX(Ratings!$F:$F,MATCH($A14,Ratings!$C:$C,0)),"") | D14: =SUMIFS(TeamGames!$X$2:$X$4073,TeamGames!$D$2:$D$4073,$A14) | E14: =SUMIFS(TeamGames!$O$2:$O$4073,TeamGames!$D$2:$D$4073,$A14) | F14: =SUMIFS(TeamGames!$S$2:$S$4073,TeamGames!$D$2:$D$4073,$A14,TeamGames!$X$2:$X$4073,1) | G14: =IF(D14=0,"",E14-F14) | H14: =SUMIFS(TeamGames!$W$2:$W$4073,TeamGames!$D$2:$D$4073,$A14) | I14: =IF(D14=0,"",H14-F14) | J14: =SUMIFS(TeamGames!$T$2:$T$4073,TeamGames!$D$2:$D$4073,$A14) | K14: =SUMIFS(TeamGames!$U$2:$U$4073,TeamGames!$D$2:$D$4073,$A14) | L14: =IFERROR(INDEX(Blocks!$N$2:$N$1065,MATCH($A14&"|1",Blocks!$A$2:$A$1065,0)),"") | M14: =IF(IFERROR(INDEX(Blocks!$M$2:$M$1065,MATCH($A14&"|1",Blocks!$A$2:$A$1065,0)),"")=0,"",IFERROR(INDEX(Blocks!$P$2:$P$1065,MATCH($A14&"|1",Blocks!$A$2:$A$1065,0)),"")) | N14: =IF(IFERROR(INDEX(Blocks!$M$2:$M$1065,MATCH($A14&"|1",Blocks!$A$2:$A$1065,0)),"")=0,"",IFERROR(INDEX(Blocks!$S$2:$S$1065,MATCH($A14&"|1",Blocks!$A$2:$A$1065,0)),"")) | O14: =IFERROR(INDEX(Blocks!$T$2:$T$1065,MATCH($A14&"|1",Blocks!$A$2:$A$1065,0)),"") | P14: =IFERROR(INDEX(Blocks!$N$2:$N$1065,MATCH($A14&"|2",Blocks!$A$2:$A$1065,0)),"") | Q14: =IF(IFERROR(INDEX(Blocks!$M$2:$M$1065,MATCH($A14&"|2",Blocks!$A$2:$A$1065,0)),"")=0,"",IFERROR(INDEX(Blocks!$P$2:$P$1065,MATCH($A14&"|2",Blocks!$A$2:$A$1065,0)),"")) | R14: =IF(IFERROR(INDEX(Blocks!$M$2:$M$1065,MATCH($A14&"|2",Blocks!$A$2:$A$1065,0)),"")=0,"",IFERROR(INDEX(Blocks!$S$2:$S$1065,MATCH($A14&"|2",Blocks!$A$2:$A$1065,0)),"")) | S14: =IFERROR(INDEX(Blocks!$T$2:$T$1065,MATCH($A14&"|2",Blocks!$A$2:$A$1065,0)),"") | T14: =IFERROR(INDEX(Blocks!$N$2:$N$1065,MATCH($A14&"|3",Blocks!$A$2:$A$1065,0)),"") | U14: =IF(IFERROR(INDEX(Blocks!$M$2:$M$1065,MATCH($A14&"|3",Blocks!$A$2:$A$1065,0)),"")=0,"",IFERROR(INDEX(Blocks!$P$2:$P$1065,MATCH($A14&"|3",Blocks!$A$2:$A$1065,0)),"")) | V14: =IF(IFERROR(INDEX(Blocks!$M$2:$M$1065,MATCH($A14&"|3",Blocks!$A$2:$A$1065,0)),"")=0,"",IFERROR(INDEX(Blocks!$S$2:$S$1065,MATCH($A14&"|3",Blocks!$A$2:$A$1065,0)),"")) | W14: =IFERROR(INDEX(Blocks!$T$2:$T$1065,MATCH($A14&"|3",Blocks!$A$2:$A$1065,0)),"") | X14: =IFERROR(INDEX(Blocks!$N$2:$N$1065,MATCH($A14&"|4",Blocks!$A$2:$A$1065,0)),"") | Y14: =IF(IFERROR(INDEX(Blocks!$M$2:$M$1065,MATCH($A14&"|4",Blocks!$A$2:$A$1065,0)),"")=0,"",IFERROR(INDEX(Blocks!$P$2:$P$1065,MATCH($A14&"|4",Blocks!$A$2:$A$1065,0)),"")) | Z14: =IF(IFERROR(INDEX(Blocks!$M$2:$M$1065,MATCH($A14&"|4",Blocks!$A$2:$A$1065,0)),"")=0,"",IFERROR(INDEX(Blocks!$S$2:$S$1065,MATCH($A14&"|4",Blocks!$A$2:$A$1065,0)),"")) | AA14: =IFERROR(INDEX(Blocks!$T$2:$T$1065,MATCH($A14&"|4",Blocks!$A$2:$A$1065,0)),"") | AB14: =IFERROR(INDEX(Blocks!$N$2:$N$1065,MATCH($A14&"|5",Blocks!$A$2:$A$1065,0)),"") | AC14: =IF(IFERROR(INDEX(Blocks!$M$2:$M$1065,MATCH($A14&"|5",Blocks!$A$2:$A$1065,0)),"")=0,"",IFERROR(INDEX(Blocks!$P$2:$P$1065,MATCH($A14&"|5",Blocks!$A$2:$A$1065,0)),"")) | AD14: =IF(IFERROR(INDEX(Blocks!$M$2:$M$1065,MATCH($A14&"|5",Blocks!$A$2:$A$1065,0)),"")=0,"",IFERROR(INDEX(Blocks!$S$2:$S$1065,MATCH($A14&"|5",Blocks!$A$2:$A$1065,0)),"")) | AE14: =IFERROR(INDEX(Blocks!$T$2:$T$1065,MATCH($A14&"|5",Blocks!$A$2:$A$1065,0)),"") | AF14: =IFERROR(INDEX(Blocks!$N$2:$N$1065,MATCH($A14&"|6",Blocks!$A$2:$A$1065,0)),"") | AG14: =IF(IFERROR(INDEX(Blocks!$M$2:$M$1065,MATCH($A14&"|6",Blocks!$A$2:$A$1065,0)),"")=0,"",IFERROR(INDEX(Blocks!$P$2:$P$1065,MATCH($A14&"|6",Blocks!$A$2:$A$1065,0)),"")) | AH14: =IF(IFERROR(INDEX(Blocks!$M$2:$M$1065,MATCH($A14&"|6",Blocks!$A$2:$A$1065,0)),"")=0,"",IFERROR(INDEX(Blocks!$S$2:$S$1065,MATCH($A14&"|6",Blocks!$A$2:$A$1065,0)),"")) | AI14: =IFERROR(INDEX(Blocks!$T$2:$T$1065,MATCH($A14&"|6",Blocks!$A$2:$A$1065,0)),"") | AJ14: =IFERROR(INDEX(Blocks!$N$2:$N$1065,MATCH($A14&"|7",Blocks!$A$2:$A$1065,0)),"") | AK14: =IF(IFERROR(INDEX(Blocks!$M$2:$M$1065,MATCH($A14&"|7",Blocks!$A$2:$A$1065,0)),"")=0,"",IFERROR(INDEX(Blocks!$P$2:$P$1065,MATCH($A14&"|7",Blocks!$A$2:$A$1065,0)),"")) | AL14: =IF(IFERROR(INDEX(Blocks!$M$2:$M$1065,MATCH($A14&"|7",Blocks!$A$2:$A$1065,0)),"")=0,"",IFERROR(INDEX(Blocks!$S$2:$S$1065,MATCH($A14&"|7",Blocks!$A$2:$A$1065,0)),"")) | AM14: =IFERROR(INDEX(Blocks!$T$2:$T$1065,MATCH($A14&"|7",Blocks!$A$2:$A$1065,0)),"") | AN14: =IFERROR(INDEX(Blocks!$N$2:$N$1065,MATCH($A14&"|8",Blocks!$A$2:$A$1065,0)),"") | AO14: =IF(IFERROR(INDEX(Blocks!$M$2:$M$1065,MATCH($A14&"|8",Blocks!$A$2:$A$1065,0)),"")=0,"",IFERROR(INDEX(Blocks!$P$2:$P$1065,MATCH($A14&"|8",Blocks!$A$2:$A$1065,0)),"")) | AP14: =IF(IFERROR(INDEX(Blocks!$M$2:$M$1065,MATCH($A14&"|8",Blocks!$A$2:$A$1065,0)),"")=0,"",IFERROR(INDEX(Blocks!$S$2:$S$1065,MATCH($A14&"|8",Blocks!$A$2:$A$1065,0)),"")) | AQ14: =IFERROR(INDEX(Blocks!$T$2:$T$1065,MATCH($A14&"|8",Blocks!$A$2:$A$1065,0)),"") | AR14: =IFERROR(INDEX(Blocks!$N$2:$N$1065,MATCH($A14&"|9",Blocks!$A$2:$A$1065,0)),"") | AS14: =IF(IFERROR(INDEX(Blocks!$M$2:$M$1065,MATCH($A14&"|9",Blocks!$A$2:$A$1065,0)),"")=0,"",IFERROR(INDEX(Blocks!$P$2:$P$1065,MATCH($A14&"|9",Blocks!$A$2:$A$1065,0)),"")) | AT14: =IF(IFERROR(INDEX(Blocks!$M$2:$M$1065,MATCH($A14&"|9",Blocks!$A$2:$A$1065,0)),"")=0,"",IFERROR(INDEX(Blocks!$S$2:$S$1065,MATCH($A14&"|9",Blocks!$A$2:$A$1065,0)),"")) | AU14: =IFERROR(INDEX(Blocks!$T$2:$T$1065,MATCH($A14&"|9",Blocks!$A$2:$A$1065,0)),"") | AV14: =IFERROR(INDEX(Blocks!$N$2:$N$1065,MATCH($A14&"|10",Blocks!$A$2:$A$1065,0)),"") | AW14: =IF(IFERROR(INDEX(Blocks!$M$2:$M$1065,MATCH($A14&"|10",Blocks!$A$2:$A$1065,0)),"")=0,"",IFERROR(INDEX(Blocks!$P$2:$P$1065,MATCH($A14&"|10",Blocks!$A$2:$A$1065,0)),"")) | AX14: =IF(IFERROR(INDEX(Blocks!$M$2:$M$1065,MATCH($A14&"|10",Blocks!$A$2:$A$1065,0)),"")=0,"",IFERROR(INDEX(Blocks!$S$2:$S$1065,MATCH($A14&"|10",Blocks!$A$2:$A$1065,0)),"")) | AY14: =IFERROR(INDEX(Blocks!$T$2:$T$1065,MATCH($A14&"|10",Blocks!$A$2:$A$1065,0)),"")
